<?xml version="1.0"?>
<robot name="arduino_robot_arm">
    <!-- Base Link -->
    <link name="base_link">
        <visual>
            <geometry>
                <box size="0.1 0.1 0.02"/>
            </geometry>
            <material name="blue">
                <color rgba="0 0 1 1"/>
            </material>
        </visual>
        <collision>
            <geometry>
                <box size="0.1 0.1 0.02"/>
            </geometry>
        </collision>
        <inertial>
            <mass value="1"/>
            <inertia ixx="0.1" ixy="0" ixz="0" iyy="0.1" iyz="0" izz="0.1"/>
        </inertial>
    </link>

    <!-- Waist Joint -->
    <joint name="waist" type="revolute">
        <parent link="base_link"/>
        <child link="waist_link"/>
        <origin xyz="0 0 0.01" rpy="0 0 0"/>
        <axis xyz="0 0 1"/>
        <limit lower="-3.14" upper="3.14" effort="100" velocity="1"/>
    </joint>

    <!-- Waist Link -->
    <link name="waist_link">
        <visual>
            <geometry>
                <cylinder length="0.05" radius="0.02"/>
            </geometry>
            <material name="red">
                <color rgba="1 0 0 1"/>
            </material>
        </visual>
        <collision>
            <geometry>
                <cylinder length="0.05" radius="0.02"/>
            </geometry>
        </collision>
        <inertial>
            <mass value="0.5"/>
            <inertia ixx="0.01" ixy="0" ixz="0" iyy="0.01" iyz="0" izz="0.01"/>
        </inertial>
    </link>

    <!-- Shoulder Joint -->
    <joint name="shoulder" type="revolute">
        <parent link="waist_link"/>
        <child link="shoulder_link"/>
        <origin xyz="0 0 0.025" rpy="0 0 0"/>
        <axis xyz="0 1 0"/>
        <limit lower="-1.57" upper="1.57" effort="100" velocity="1"/>
    </joint>

    <!-- Shoulder Link -->
    <link name="shoulder_link">
        <visual>
            <geometry>
                <box size="0.02 0.02 0.1"/>
            </geometry>
            <material name="green">
                <color rgba="0 1 0 1"/>
            </material>
        </visual>
        <collision>
            <geometry>
                <box size="0.02 0.02 0.1"/>
            </geometry>
        </collision>
        <inertial>
            <mass value="0.5"/>
            <inertia ixx="0.01" ixy="0" ixz="0" iyy="0.01" iyz="0" izz="0.01"/>
        </inertial>
    </link>

    <!-- Elbow Joint -->
    <joint name="elbow" type="revolute">
        <parent link="shoulder_link"/>
        <child link="elbow_link"/>
        <origin xyz="0 0 0.1" rpy="0 0 0"/>
        <axis xyz="0 1 0"/>
        <limit lower="-1.57" upper="1.57" effort="100" velocity="1"/>
    </joint>

    <!-- Elbow Link -->
    <link name="elbow_link">
        <visual>
            <geometry>
                <box size="0.02 0.02 0.1"/>
            </geometry>
            <material name="yellow">
                <color rgba="1 1 0 1"/>
            </material>
        </visual>
        <collision>
            <geometry>
                <box size="0.02 0.02 0.1"/>
            </geometry>
        </collision>
        <inertial>
            <mass value="0.5"/>
            <inertia ixx="0.01" ixy="0" ixz="0" iyy="0.01" iyz="0" izz="0.01"/>
        </inertial>
    </link>

    <!-- Gripper Joint -->
    <joint name="gripper" type="revolute">
        <parent link="elbow_link"/>
        <child link="gripper_link"/>
        <origin xyz="0 0 0.1" rpy="0 0 0"/>
        <axis xyz="0 1 0"/>
        <limit lower="-1.57" upper="1.57" effort="100" velocity="1"/>
    </joint>

    <!-- Gripper Link -->
    <link name="gripper_link">
        <visual>
            <geometry>
                <box size="0.02 0.04 0.02"/>
            </geometry>
            <material name="white">
                <color rgba="1 1 1 1"/>
            </material>
        </visual>
        <collision>
            <geometry>
                <box size="0.02 0.04 0.02"/>
            </geometry>
        </collision>
        <inertial>
            <mass value="0.1"/>
            <inertia ixx="0.001" ixy="0" ixz="0" iyy="0.001" iyz="0" izz="0.001"/>
        </inertial>
    </link>
</robot>
